<?xml version="1.0" encoding="utf-8"?>
<!-- =================================================================================== -->
<!-- |    This document was autogenerated by xacro from as.xacro                       | -->
<!-- |    EDITING THIS FILE BY HAND IS NOT RECOMMENDED                                 | -->
<!-- =================================================================================== -->
<robot name="asArm" xmlns:controller="http://playerstage.sourceforge.net/gazebo/xmlschema/#controller" xmlns:interface="http://playerstage.sourceforge.net/gazebo/xmlschema/#interface" xmlns:sensor="http://playerstage.sourceforge.net/gazebo/xmlschema/#sensor">
  <!-- alluminium frame only -->
  <material name="Orange">
    <color rgba="1.0 0.4 0.0 1.0"/>
  </material>
  <material name="Grey">
    <color rgba="0.7 0.7 0.7 1.0"/>
  </material>
  <material name="DarkGrey">
    <color rgba="0.3 0.3 0.3 1.0"/>
  </material>
  <material name="White">
    <color rgba="1.0 1.0 1.0 1.0"/>
  </material>
  <material name="Black">
    <color rgba="0.0 0.0 0.0 1.0"/>
  </material>
  <material name="Red">
    <color rgba="1.0 0.0 0.0 1.0"/>
  </material>
  <material name="Green">
    <color rgba="0.0 1.0 0.0 1.0"/>
  </material>
  <material name="Blue">
    <color rgba="0.0 0.0 0.8 1.0"/>
  </material>
  <material name="LightGrey">
    <color rgba="0.82 0.82 0.82 1.0"/>
  </material>
  <material name="OrangeClear">
    <color rgba="1.0 0.4 0.0 .5"/>
  </material>
  <material name="GreyClear">
    <color rgba="0.7 0.7 0.7 .5"/>
  </material>
  <material name="DarkGreyClear">
    <color rgba="0.3 0.3 0.3 .5"/>
  </material>
  <material name="WhiteClear">
    <color rgba="1.0 1.0 1.0 .5"/>
  </material>
  <material name="BlackClear">
    <color rgba="0.0 0.0 0.0 .5"/>
  </material>
  <material name="RedClear">
    <color rgba="1.0 0.0 0.0 .5"/>
  </material>
  <material name="GreenClear">
    <color rgba="0.0 1.0 0.0 .5"/>
  </material>
  <material name="BlueClear">
    <color rgba="0.0 0.0 0.8 .5"/>
  </material>
  <material name="LightGreyClear">
    <color rgba="0.82 0.82 0.82 .5"/>
  </material>
  <!-- formation-->
  <!-- <xacro:as_base load_gazebo_plugin="$(arg load_gazebo_plugin)" />  -->
  <link name="base_link"/>
  <!--
  Author: Jason Peng <jason@ufactory.cc>
  Contributers:
-->
  <joint name="xarmworld_joint" type="fixed">
    <parent link="base_link"/>
    <child link="xarmlink_base"/>
    <origin rpy="0 0 0" xyz="0.175 0 -0.053"/>
  </joint>
  <material name="xarmBlack">
    <color rgba="0.0 0.0 0.0 1.0"/>
  </material>
  <material name="xarmRed">
    <color rgba="0.8 0.0 0.0 1.0"/>
  </material>
  <material name="xarmWhite">
    <color rgba="1.0 1.0 1.0 1.0"/>
  </material>
  <material name="xarmSilver">
    <color rgba="0.753 0.753 0.753 1.0"/>
  </material>
  <link name="xarmlink_base">
    <visual>
      <geometry>
        <mesh filename="package://xarm_description/meshes/xarm6/visual/base.stl"/>
      </geometry>
      <origin rpy="0 0 0" xyz="0 0 0"/>
      <material name="xarmWhite"/>
    </visual>
    <collision>
      <geometry>
        <mesh filename="package://xarm_description/meshes/xarm6/visual/base.stl"/>
      </geometry>
      <origin rpy="0 0 0" xyz="0 0 0"/>
    </collision>
    <inertial>
      <origin rpy="0 0 0" xyz="0.0 0.0 0.09103"/>
      <mass value="2.7"/>
      <inertia ixx="0.00494875" ixy="-3.5E-06" ixz="1.25E-05" iyy="0.00494174" iyz="1.67E-06" izz="0.002219"/>
    </inertial>
  </link>
  <link name="xarmlink1">
    <visual>
      <geometry>
        <mesh filename="package://xarm_description/meshes/xarm6/visual/link1.stl"/>
      </geometry>
      <origin rpy="0 0 0" xyz="0 0 0"/>
      <material name="xarmWhite"/>
    </visual>
    <collision>
      <geometry>
        <mesh filename="package://xarm_description/meshes/xarm6/visual/link1.stl"/>
      </geometry>
      <origin rpy="0 0 0" xyz="0 0 0"/>
    </collision>
    <inertial>
      <origin rpy="0 0 0" xyz="-0.002 0.02692 -0.01332"/>
      <mass value="2.16"/>
      <inertia ixx="0.00539427" ixy="1.095E-05" ixz="1.635E-06" iyy="0.0048979" iyz="0.000793" izz="0.00311573"/>
    </inertial>
  </link>
  <joint name="xarmjoint1" type="revolute">
    <parent link="xarmlink_base"/>
    <child link="xarmlink1"/>
    <origin rpy="0 0 0" xyz="0 0 0.267"/>
    <axis xyz="0 0 1"/>
    <limit effort="50.0" lower="-3.11017672705" upper="3.11017672705" velocity="3.14"/>
    <dynamics damping="1.0" friction="1.0"/>
  </joint>
  <link name="xarmlink2">
    <visual>
      <geometry>
        <mesh filename="package://xarm_description/meshes/xarm6/visual/link2.stl"/>
      </geometry>
      <origin rpy="0 0 0" xyz="0 0 0"/>
      <material name="xarmWhite"/>
    </visual>
    <collision>
      <geometry>
        <mesh filename="package://xarm_description/meshes/xarm6/visual/link2.stl"/>
      </geometry>
      <origin rpy="0 0 0" xyz="0 0 0"/>
    </collision>
    <inertial>
      <origin rpy="0 0 0" xyz="0.03531 -0.21398 0.03386"/>
      <mass value="1.71"/>
      <inertia ixx="0.0248674" ixy="-0.00430651" ixz="-0.00067797" iyy="0.00485548" iyz="0.00457245" izz="0.02387827"/>
    </inertial>
  </link>
  <joint name="xarmjoint2" type="revolute">
    <parent link="xarmlink1"/>
    <child link="xarmlink2"/>
    <origin rpy="-1.5708 0 0" xyz="0 0 0"/>
    <axis xyz="0 0 1"/>
    <limit effort="50.0" lower="-2.059" upper="2.0944" velocity="3.14"/>
    <dynamics damping="1.0" friction="1.0"/>
  </joint>
  <link name="xarmlink3">
    <visual>
      <geometry>
        <mesh filename="package://xarm_description/meshes/xarm6/visual/link3.stl"/>
      </geometry>
      <origin rpy="0 0 0" xyz="0 0 0"/>
      <material name="xarmWhite"/>
    </visual>
    <collision>
      <geometry>
        <mesh filename="package://xarm_description/meshes/xarm6/visual/link3.stl"/>
      </geometry>
      <origin rpy="0 0 0" xyz="0 0 0"/>
    </collision>
    <inertial>
      <origin rpy="0 0 0" xyz="0.06781 0.10749 0.01457"/>
      <mass value="1.384"/>
      <inertia ixx="0.0053694" ixy="0.0014185" ixz="-0.00092094" iyy="0.0032423" iyz="-0.00169178" izz="0.00501731"/>
    </inertial>
  </link>
  <joint name="xarmjoint3" type="revolute">
    <parent link="xarmlink2"/>
    <child link="xarmlink3"/>
    <origin rpy="0 0 0" xyz="0.0535 -0.2845 0"/>
    <axis xyz="0 0 1"/>
    <limit effort="32.0" lower="-3.11017672705" upper="0.19198" velocity="3.14"/>
    <dynamics damping="1.0" friction="1.0"/>
  </joint>
  <link name="xarmlink4">
    <visual>
      <geometry>
        <mesh filename="package://xarm_description/meshes/xarm6/visual/link4.stl"/>
      </geometry>
      <origin rpy="0 0 0" xyz="0 0 0"/>
      <material name="xarmWhite"/>
    </visual>
    <collision>
      <geometry>
        <mesh filename="package://xarm_description/meshes/xarm6/visual/link4.stl"/>
      </geometry>
      <origin rpy="0 0 0" xyz="0 0 0"/>
    </collision>
    <inertial>
      <origin rpy="0 0 0" xyz="-0.00021 0.02578 -0.02538"/>
      <mass value="1.115"/>
      <inertia ixx="0.00439263" ixy="5.028E-05" ixz="1.374E-05" iyy="0.0040077" iyz="0.00045338" izz="0.00110321"/>
    </inertial>
  </link>
  <joint name="xarmjoint4" type="revolute">
    <parent link="xarmlink3"/>
    <child link="xarmlink4"/>
    <origin rpy="-1.5708 0 0" xyz="0.0775 0.3425 0"/>
    <axis xyz="0 0 1"/>
    <limit effort="32.0" lower="-3.11017672705" upper="3.11017672705" velocity="3.14"/>
    <dynamics damping="1.0" friction="1.0"/>
  </joint>
  <link name="xarmlink5">
    <visual>
      <geometry>
        <mesh filename="package://xarm_description/meshes/xarm6/visual/link5.stl"/>
      </geometry>
      <origin rpy="0 0 0" xyz="0 0 0"/>
      <material name="xarmWhite"/>
    </visual>
    <collision>
      <geometry>
        <mesh filename="package://xarm_description/meshes/xarm6/visual/link5.stl"/>
      </geometry>
      <origin rpy="0 0 0" xyz="0 0 0"/>
    </collision>
    <inertial>
      <origin rpy="0 0 0" xyz="0.05428 0.01781 0.00543"/>
      <mass value="1.275"/>
      <inertia ixx="0.001202758" ixy="0.000492428" ixz="-0.00039147" iyy="0.0022876" iyz="-1.235E-04" izz="0.0026866"/>
    </inertial>
  </link>
  <joint name="xarmjoint5" type="revolute">
    <parent link="xarmlink4"/>
    <child link="xarmlink5"/>
    <origin rpy="1.5708 0 0" xyz="0 0 0"/>
    <axis xyz="0 0 1"/>
    <limit effort="32.0" lower="-1.69297" upper="3.11017672705" velocity="3.14"/>
    <dynamics damping="1.0" friction="1.0"/>
  </joint>
  <link name="xarmlink6">
    <visual>
      <geometry>
        <mesh filename="package://xarm_description/meshes/xarm6/visual/link6.stl"/>
      </geometry>
      <origin rpy="0 0 0" xyz="0 0 0"/>
      <material name="xarmSilver"/>
    </visual>
    <collision>
      <geometry>
        <mesh filename="package://xarm_description/meshes/xarm6/visual/link6.stl"/>
      </geometry>
      <origin rpy="0 0 0" xyz="0 0 0"/>
    </collision>
    <inertial>
      <origin rpy="0 0 0" xyz="0 0.00064 -0.00952"/>
      <mass value="0.1096"/>
      <inertia ixx="4.5293E-05" ixy="0" ixz="0" iyy="4.8111E-05" iyz="0" izz="7.9715E-05"/>
    </inertial>
  </link>
  <joint name="xarmjoint6" type="revolute">
    <parent link="xarmlink5"/>
    <child link="xarmlink6"/>
    <origin rpy="-1.5708 0 0" xyz="0.076 0.097 0"/>
    <axis xyz="0 0 1"/>
    <limit effort="20.0" lower="-3.11017672705" upper="3.11017672705" velocity="3.14"/>
    <dynamics damping="1.0" friction="1.0"/>
  </joint>
  <link name="xarmlink_eef"/>
  <joint name="xarmjoint_eef" type="fixed">
    <origin rpy="0 0 0" xyz="0 0 0"/>
    <parent link="xarmlink6"/>
    <child link="xarmlink_eef"/>
  </joint>
  <transmission name="xarmtran1">
    <type>transmission_interface/SimpleTransmission</type>
    <joint name="xarmjoint1">
      <hardwareInterface>hardware_interface/PositionJointInterface</hardwareInterface>
    </joint>
    <actuator name="xarmmotor1">
      <hardwareInterface>hardware_interface/PositionJointInterface</hardwareInterface>
      <mechanicalReduction>100</mechanicalReduction>
    </actuator>
  </transmission>
  <transmission name="xarmtran2">
    <type>transmission_interface/SimpleTransmission</type>
    <joint name="xarmjoint2">
      <hardwareInterface>hardware_interface/PositionJointInterface</hardwareInterface>
    </joint>
    <actuator name="xarmmotor2">
      <hardwareInterface>hardware_interface/PositionJointInterface</hardwareInterface>
      <mechanicalReduction>100</mechanicalReduction>
    </actuator>
  </transmission>
  <transmission name="xarmtran3">
    <type>transmission_interface/SimpleTransmission</type>
    <joint name="xarmjoint3">
      <hardwareInterface>hardware_interface/PositionJointInterface</hardwareInterface>
    </joint>
    <actuator name="xarmmotor3">
      <hardwareInterface>hardware_interface/PositionJointInterface</hardwareInterface>
      <mechanicalReduction>100</mechanicalReduction>
    </actuator>
  </transmission>
  <transmission name="xarmtran4">
    <type>transmission_interface/SimpleTransmission</type>
    <joint name="xarmjoint4">
      <hardwareInterface>hardware_interface/PositionJointInterface</hardwareInterface>
    </joint>
    <actuator name="xarmmotor3">
      <hardwareInterface>hardware_interface/PositionJointInterface</hardwareInterface>
      <mechanicalReduction>100</mechanicalReduction>
    </actuator>
  </transmission>
  <transmission name="xarmtran5">
    <type>transmission_interface/SimpleTransmission</type>
    <joint name="xarmjoint5">
      <hardwareInterface>hardware_interface/PositionJointInterface</hardwareInterface>
    </joint>
    <actuator name="xarmmotor5">
      <hardwareInterface>hardware_interface/PositionJointInterface</hardwareInterface>
      <mechanicalReduction>100</mechanicalReduction>
    </actuator>
  </transmission>
  <transmission name="xarmtran6">
    <type>transmission_interface/SimpleTransmission</type>
    <joint name="xarmjoint6">
      <hardwareInterface>hardware_interface/PositionJointInterface</hardwareInterface>
    </joint>
    <actuator name="xarmmotor6">
      <hardwareInterface>hardware_interface/PositionJointInterface</hardwareInterface>
      <mechanicalReduction>100</mechanicalReduction>
    </actuator>
  </transmission>
  <gazebo reference="xarmlink_base">
    <selfCollide>true</selfCollide>
  </gazebo>
  <gazebo reference="xarmlink1">
    <selfCollide>true</selfCollide>
  </gazebo>
  <gazebo reference="xarmlink2">
    <selfCollide>true</selfCollide>
  </gazebo>
  <gazebo reference="xarmlink3">
    <selfCollide>true</selfCollide>
  </gazebo>
  <gazebo reference="xarmlink4">
    <selfCollide>true</selfCollide>
  </gazebo>
  <gazebo reference="xarmlink5">
    <selfCollide>true</selfCollide>
  </gazebo>
  <gazebo reference="xarmlink6">
    <selfCollide>true</selfCollide>
  </gazebo>
  <joint name="extruder_joint" type="fixed">
    <parent link="xarmlink_eef"/>
    <child link="extruder_link"/>
    <origin rpy="0 0 -1.57079632679" xyz="0 0 0.085"/>
  </joint>
  <link name="extruder_link">
    <inertial>
      <origin rpy="0 0 0" xyz="0 0 0"/>
      <mass value="1.05"/>
      <inertia ixx="0.003185" ixy="0" ixz="0" iyy="0.003185" iyz="0" izz="0.0013125"/>
    </inertial>
    <visual>
      <origin rpy="0 0 0" xyz="0 0 -0.085"/>
      <geometry>
        <mesh filename="package://as_description/meshes/extruder.dae"/>
      </geometry>
    </visual>
    <collision>
      <origin rpy="0 0 0" xyz="0 0 -0.085"/>
      <geometry>
        <mesh filename="package://as_description/meshes/extruder_collision.dae"/>
      </geometry>
    </collision>
  </link>
  <link name="extruder_ee"/>
  <joint name="extruder_ee_joint" type="fixed">
    <parent link="extruder_link"/>
    <child link="extruder_ee"/>
    <origin rpy="0 0 0" xyz="0 0 0.085"/>
  </joint>
  <!-- Gazebo: My current understanding is that libgazebo_ros_control is a per-model-plugin
      and most recent spawn will override the last one. So there is no nice way to namespace this.
      Therefore the approach here disables individual base/arm plugins and launches a common one -->
  <gazebo>
    <plugin filename="libgazebo_ros_control.so" name="armstone_gazebo_ros_control">
      <robotNamespace>/as_control</robotNamespace>
    </plugin>
  </gazebo>
</robot>
